Iniciando escaneo de Followers para: alvarouribevel, desde cursor:156710726412023276
Iniciando escaneo de Followers para: alvarouribevel, desde cursor:-1
Traceback (most recent call last):
  File "followers.py", line 45, in <module>
    ids100 = twitter_api.users.lookup(user_id=",".join([str(x) for x in las50[i]]))
  File "/usr/local/lib/python2.7/dist-packages/twitter/api.py", line 312, in __call__
    return self._handle_response(req, uri, arg_data, _timeout)
  File "/usr/local/lib/python2.7/dist-packages/twitter/api.py", line 345, in _handle_response
    raise TwitterHTTPError(e, uri, self.format, arg_data)
twitter.api.TwitterHTTPError: Twitter sent status 503 for URL: 1.1/users/lookup.json using parameters: (oauth_consumer_key=hpnF9vVWgNqIeYXRBfizftNlL&oauth_nonce=3558474662212305482&oauth_signature_method=HMAC-SHA1&oauth_timestamp=1500293050&oauth_token=739284017770573825-lyyOg0ngqF522MJV3rbiudGAWzqbjti&oauth_version=1.0&user_id=850745471081607168%2C850744781571584003%2C850704958538362880%2C850745625650102272%2C792501390%2C124852920%2C850744684670595073%2C850742781500956676%2C850742842985152514%2C850742694305562626%2C759699276%2C850742257670082560%2C850742580933533698%2C850740871649800194%2C1575910506%2C850740902159163392%2C850736875526651909%2C850739735614115840%2C850740135012573185%2C749685586294870016%2C850738295315345409%2C850736965104402432%2C850479064045543425%2C850736043301249029%2C850736198205272064%2C999847800%2C850735019245129730%2C850735450423779330%2C746893902523826176%2C83189109%2C850732564050587648%2C850565978375299073%2C850732091910365185%2C850732817361272832%2C850730967778119680%2C850732008330465282%2C850732016106688513%2C850731965774954496%2C850724445958406144%2C850731672819597312%2C3533655203%2C837012937348943873%2C850175536559271937%2C631977756%2C198650677%2C850729218635952128%2C850727966552330241%2C850727573722148864%2C850727707054919684%2C850728028699332609%2C850727197266644992%2C850726626501513216%2C850724910477475840%2C850725663275438082%2C369872355%2C830485489316687878%2C850722067741896705%2C850722016441323521%2C849467018990452737%2C850723284547235841%2C850723373210619904%2C850721146639192064%2C2953705775%2C850721735548784640%2C3215086215%2C140517059%2C850719863291170820%2C838170316329390080%2C850717965905428480%2C850321728685387777%2C850717151073906688%2C850717461892796416%2C850717305629810689%2C850717016403173380%2C167131278%2C2861901637%2C849399190727913472%2C817430079533891589%2C850714676048613382%2C850714772840611840%2C850713941395337216%2C848052334139670528%2C850519007488856064%2C850711263193817088%2C795703275379163136%2C850708808737357824%2C850708637135851520%2C711524215036514304%2C850707868269654017%2C850707019824861184%2C926007228%2C850149390832500736%2C850706934231695360%2C73635216%2C850706452608159744%2C842483868640956416%2C850704297625096192%2C313594921%2C716799107986272264%2C813175749532413953&oauth_signature=MLtbROasFGoXzTaneeta9pt%2B928%3D)
details: {u'errors': [{u'message': u'Over capacity', u'code': 130}]}
Iniciando escaneo de Followers para: alvarouribevel, desde cursor:1564606555527851952
Traceback (most recent call last):
  File "followers.py", line 45, in <module>
    ids100 = twitter_api.users.lookup(user_id=",".join([str(x) for x in las50[i]]))
  File "/usr/local/lib/python2.7/dist-packages/twitter/api.py", line 312, in __call__
    return self._handle_response(req, uri, arg_data, _timeout)
  File "/usr/local/lib/python2.7/dist-packages/twitter/api.py", line 345, in _handle_response
    raise TwitterHTTPError(e, uri, self.format, arg_data)
twitter.api.TwitterHTTPError: Twitter sent status 503 for URL: 1.1/users/lookup.json using parameters: (oauth_consumer_key=hpnF9vVWgNqIeYXRBfizftNlL&oauth_nonce=15136517451057688942&oauth_signature_method=HMAC-SHA1&oauth_timestamp=1500317122&oauth_token=739284017770573825-lyyOg0ngqF522MJV3rbiudGAWzqbjti&oauth_version=1.0&user_id=4221081831%2C4800016695%2C4800130966%2C4800007761%2C4800019893%2C4799999313%2C4800024917%2C4798612401%2C329801353%2C4800015441%2C4800113422%2C1875812606%2C4800035165%2C4157754513%2C1445330569%2C4800051683%2C4799959515%2C4799983743%2C3056359784%2C4799949741%2C4800088582%2C4662656369%2C4798797496%2C4799981727%2C3191533036%2C4799964795%2C2448899190%2C4799992337%2C4800078046%2C4800043840%2C4799934135%2C4799929083%2C4799897781%2C4799940441%2C4799955471%2C4731208360%2C614660795%2C4800038662%2C4799961275%2C139549184%2C4799173041%2C579119528%2C4514746583%2C1618213453%2C4729067662%2C4799954609%2C4799942585%2C2968640512%2C4799979562%2C2306974146%2C1343279018%2C4800003868%2C4799886495%2C4307412501%2C4799358209%2C4323795922%2C4799869761%2C2467101127%2C805393861%2C205105007%2C4799796981%2C4799860515%2C3205645131%2C4799906777%2C2975870339%2C4798998983%2C145826239%2C4625665415%2C4799771259%2C4799963062%2C4799892569%2C494094150%2C3798930148%2C4799861902%2C268142307%2C1216344554%2C4799923576%2C3285999787%2C4799894777%2C4799865557%2C4799876249%2C4799804392%2C757096862%2C4799581348%2C4799808675%2C4799867777%2C4799882116%2C2329357941%2C4541190448%2C4568900547%2C4799706616%2C4799843189%2C235145444%2C1226312822%2C4482090255%2C2981571941%2C4776845500%2C261442333%2C260740230%2C4799774403&oauth_signature=oGYEVEG3y0XM9XoQ2K887hC4Cbk%3D)
details: {}
Iniciando escaneo de Followers para: alvarouribevel, desde cursor:1523443194971831522
Traceback (most recent call last):
  File "followers.py", line 45, in <module>
    ids100 = twitter_api.users.lookup(user_id=",".join([str(x) for x in las50[i]]))
  File "/usr/local/lib/python2.7/dist-packages/twitter/api.py", line 312, in __call__
    return self._handle_response(req, uri, arg_data, _timeout)
  File "/usr/local/lib/python2.7/dist-packages/twitter/api.py", line 345, in _handle_response
    raise TwitterHTTPError(e, uri, self.format, arg_data)
twitter.api.TwitterHTTPError: Twitter sent status 503 for URL: 1.1/users/lookup.json using parameters: (oauth_consumer_key=hpnF9vVWgNqIeYXRBfizftNlL&oauth_nonce=13673116962029221158&oauth_signature_method=HMAC-SHA1&oauth_timestamp=1500322223&oauth_token=739284017770573825-lyyOg0ngqF522MJV3rbiudGAWzqbjti&oauth_version=1.0&user_id=1310220488%2C290088743%2C3763048221%2C65169926%2C3748861937%2C1719593953%2C3763092383%2C3763164796%2C344231013%2C3026420055%2C3763147168%2C2723810613%2C2591143340%2C2336751430%2C3711787636%2C1100985013%2C2743416525%2C357676590%2C3763027575%2C2147531849%2C522873517%2C153062697%2C460345638%2C3437565983%2C127669292%2C3706560389%2C2858416472%2C2827822539%2C3707694928%2C1478217842%2C125224799%2C64033125%2C2253099541%2C3763024396%2C1245060631%2C199391805%2C3763003755%2C241216765%2C3762929301%2C3763048037%2C2245668911%2C3763103842%2C2172619095%2C902320880%2C75128193%2C305708667%2C3763013903%2C3763009757%2C333106541%2C1300279886%2C3762977115%2C476857128%2C256286497%2C2494349275%2C3755476816%2C898699938%2C205716369%2C129574822%2C3514069577%2C62089848%2C3763045642%2C3762974116%2C3402192885%2C563264672%2C3385913231%2C3762851301%2C3179796819%2C96508605%2C293298694%2C782893699%2C2869628775%2C3763008328%2C3236665593%2C392474065%2C181552391%2C314877247%2C3762934948%2C238319154%2C3351426263%2C2849943323%2C69422888%2C3314095547%2C961390002%2C2338290620%2C2315097359%2C480933395%2C148834986%2C1225769772%2C69962868%2C3762872955%2C160449705%2C110862977%2C453715887%2C3762974848%2C3762982042%2C82741085%2C274057459%2C2605441910%2C3236924241%2C436118739&oauth_signature=EZUbdZC%2B2qAi6fLHrKS1Ds3Ad6s%3D)
details: {u'errors': [{u'message': u'Over capacity', u'code': 130}]}
Iniciando escaneo de Followers para: alvarouribevel, desde cursor:1513217079214023488
Traceback (most recent call last):
  File "followers.py", line 47, in <module>
    json.dump(ids100, outfile)
  File "/usr/lib/python2.7/json/__init__.py", line 190, in dump
    fp.write(chunk)
IOError: [Errno 28] No space left on device
Iniciando escaneo de Followers para: alvarouribevel, desde cursor:1469267171117653545
Traceback (most recent call last):
  File "followers.py", line 47, in <module>
    json.dump(ids100, outfile)
  File "/usr/lib/python2.7/json/__init__.py", line 190, in dump
    fp.write(chunk)
IOError: [Errno 28] No space left on device
Iniciando escaneo de Followers para: alvarouribevel, desde cursor:1462233999029032281
Iniciando escaneo de Followers para: juanmansantos, desde cursor:1565431254872239847
Traceback (most recent call last):
  File "followers.py", line 45, in <module>
    ids100 = twitter_api.users.lookup(user_id=",".join([str(x) for x in las50[i]]))
  File "/usr/local/lib/python2.7/dist-packages/twitter/api.py", line 312, in __call__
    return self._handle_response(req, uri, arg_data, _timeout)
  File "/usr/local/lib/python2.7/dist-packages/twitter/api.py", line 345, in _handle_response
    raise TwitterHTTPError(e, uri, self.format, arg_data)
twitter.api.TwitterHTTPError: Twitter sent status 503 for URL: 1.1/users/lookup.json using parameters: (oauth_consumer_key=hpnF9vVWgNqIeYXRBfizftNlL&oauth_nonce=4888465959569374430&oauth_signature_method=HMAC-SHA1&oauth_timestamp=1501065578&oauth_token=739284017770573825-lyyOg0ngqF522MJV3rbiudGAWzqbjti&oauth_version=1.0&user_id=2736292707%2C2736285093%2C2736290727%2C2735302757%2C2714851278%2C2736307379%2C220891730%2C2161012407%2C2736284817%2C2714836806%2C2548807928%2C2736299891%2C2714822316%2C2736266415%2C2710366854%2C1293087372%2C2579174931%2C2736317734%2C2707189439%2C2714849822%2C2736316270%2C2736313510%2C2292324959%2C2684858015%2C2714858672%2C2714836572%2C2714881129%2C2714834496%2C2736298535%2C2736297665%2C2565405993%2C2714855894%2C2714840198%2C2736274925%2C2701269457%2C841661215%2C2712188384%2C2715078015%2C2736286823%2C2725160422%2C1872525901%2C2735763933%2C2680350008%2C2714865409%2C2736288407%2C2588414654%2C2714865229%2C2734694073%2C2714840618%2C2714829956%2C2714810058%2C2714734663%2C2721053818%2C414218653%2C2733561201%2C2714857855%2C2736265911%2C2714853409%2C2714809740%2C2736266613%2C2736276725%2C969204560%2C2736266229%2C2450269848%2C2696165730%2C2701806895%2C2714848141%2C2736267315%2C323049799%2C2736266643%2C2714846401%2C734767626%2C2736281927%2C2736246131%2C2725835818%2C2736298948%2C2723106730%2C2736263967%2C210632812%2C510035013%2C247042969%2C153940542%2C2736257973%2C2714841463%2C2736292324%2C2290003753%2C835821752%2C2735723097%2C2736291472%2C2714833531%2C2706694650%2C2714805290%2C2714787996%2C2736255153%2C854923501%2C2350815679%2C950975958%2C89030065%2C2226692580%2C243000570&oauth_signature=I4Y9HsdlOEphU9pt9oZiClk7E44%3D)
details: {u'errors': [{u'message': u'Over capacity', u'code': 130}]}
Iniciando escaneo de Followers para: juanmansantos, desde cursor:1415726978438432042
